ValueError: Invalid value of type 'builtins.range' received for the 'x' property of scatter Received value: range(0, 1000) The 'x' property is an array that may be specified as a tuple, list, numpy array, or pandas Series
Traceback:
File "/home/runner/MonteCarloBusinessAnalyzer/.pythonlibs/lib/python3.11/site-packages/streamlit/runtime/scriptrunner/exec_code.py", line 88, in exec_func_with_error_handling
    result = func()
             ^^^^^^
File "/home/runner/MonteCarloBusinessAnalyzer/.pythonlibs/lib/python3.11/site-packages/streamlit/runtime/scriptrunner/script_runner.py", line 579, in code_to_exec
    exec(code, module.__dict__)
File "/home/runner/MonteCarloBusinessAnalyzer/main.py", line 124, in <module>
    main()
File "/home/runner/MonteCarloBusinessAnalyzer/main.py", line 108, in main
    fig = plot_simulation_results(results['simulated_data'], results['ci_lower'], results['ci_upper'], target_column, plot_type=graph_type)
          ^^^^^^^^^^^^^^^^^^^^^^^^^^^^^^^^^^^^^^^^^^^^^^^^^^^^^^^^^^^^^^^^^^^^^^^^^^^^^^^^^^^^^^^^^^^^^^^^^^^^^^^^^^^^^^^^^^^^^^^^^^^^^^^^^
File "/home/runner/MonteCarloBusinessAnalyzer/visualization.py", line 9, in plot_simulation_results
    return plot_line(simulated_data, ci_lower, ci_upper, target_column)
           ^^^^^^^^^^^^^^^^^^^^^^^^^^^^^^^^^^^^^^^^^^^^^^^^^^^^^^^^^^^^
File "/home/runner/MonteCarloBusinessAnalyzer/visualization.py", line 43, in plot_line
    fig.add_trace(go.Scatter(x=x, y=simulated_data, mode='lines', name="Simulation Results"))
                  ^^^^^^^^^^^^^^^^^^^^^^^^^^^^^^^^^^^^^^^^^^^^^^^^^^^^^^^^^^^^^^^^^^^^^^^^^^
File "/home/runner/MonteCarloBusinessAnalyzer/.pythonlibs/lib/python3.11/site-packages/plotly/graph_objs/_scatter.py", line 3634, in __init__
    self["x"] = _v
    ~~~~^^^^^
File "/home/runner/MonteCarloBusinessAnalyzer/.pythonlibs/lib/python3.11/site-packages/plotly/basedatatypes.py", line 4868, in __setitem__
    self._set_prop(prop, value)
File "/home/runner/MonteCarloBusinessAnalyzer/.pythonlibs/lib/python3.11/site-packages/plotly/basedatatypes.py", line 5212, in _set_prop
    raise err
File "/home/runner/MonteCarloBusinessAnalyzer/.pythonlibs/lib/python3.11/site-packages/plotly/basedatatypes.py", line 5207, in _set_prop
    val = validator.validate_coerce(val)
          ^^^^^^^^^^^^^^^^^^^^^^^^^^^^^^
File "/home/runner/MonteCarloBusinessAnalyzer/.pythonlibs/lib/python3.11/site-packages/_plotly_utils/basevalidators.py", line 412, in validate_coerce
    self.raise_invalid_val(v)
File "/home/runner/MonteCarloBusinessAnalyzer/.pythonlibs/lib/python3.11/site-packages/_plotly_utils/basevalidators.py", line 296, in raise_invalid_val
    raise ValueError(